Workbook
Name Slicer_Category_Clean: #N/A
Name Slicer_Month: #N/A
Name Slicer_PaymentMode_Clean: #N/A

Sheet Raw_Data
A1: Date | B1: category | C1: sub category | D1: description | E1: Amount | F1: Payment mode | G1: location | H1: remarks
A2: 45658 | B2: food | C2: lunch | D2: canteen | E2: 200/- | F2: upi | G2: outside
A3: 45689 | B3: Food | C3: dinner | D3: zomato | E3: 280rs | F3: UPI | G3: home | H3: late
A4: 45717 | B4: Food | E4: 90 | F4: cash | G4: outside
A5: 45748 | B5: Travel | C5: Bus | D5: college bus | E5: 40 | F5: cash | G5: outside
A6: 45778 | B6: Entertainment | C6: Movie | E6: 350 | F6: card | G6: mall
A7: 45809 | B7: Food | E7: 90 | F7: cash | G7: outside
A8: 45839 | B8: Travel | C8: Bus | D8: college bus | E8: 40 | F8: cash | G8: outside
A9: 45870 | B9: Entertainment | C9: Movie | E9: 350 | F9: card | G9: mall
A10: 45901 | B10: food | C10: lunch | D10: canteen | E10: 200/- | F10: upi | G10: outside
A11: 45931 | B11: Food | C11: dinner | D11: zomato | E11: 280rs | F11: UPI | G11: home | H11: late
A12: 45962 | B12: Food | E12: 90 | F12: cash | G12: outside
A13: 45992 | B13: Food | C13: dinner | D13: zomato | E13: 280rs | F13: UPI | G13: home | H13: late
A14: 46023 | B14: Food | E14: 90 | F14: cash | G14: outside
A15: 46054 | B15: Travel | C15: Bus | D15: college bus | E15: 40 | F15: cash | G15: outside
A16: 46082 | B16: Entertainment | C16: Movie | E16: 350 | F16: card | G16: mall
A17: 46113 | B17: Food | E17: 90 | F17: cash | G17: outside
A18: 46143 | B18: Travel | C18: Bus | D18: college bus | E18: 40 | F18: cash | G18: outside
A19: 46174 | B19: Entertainment | C19: Movie | E19: 350 | F19: card | G19: mall
A20: 46204 | B20: Entertainment | C20: Movie | E20: 350 | F20: card | G20: mall
A21: 46235 | B21: Food | E21: 90 | F21: cash | G21: outside
A22: 46266 | B22: food | C22: lunch | D22: canteen | E22: 200/- | F22: upi | G22: outside
A23: 46296 | B23: Food | C23: dinner | D23: zomato | E23: 280rs | F23: UPI | G23: home | H23: late
A24: 46327 | B24: Food | E24: 90 | F24: cash | G24: outside
A25: 46357 | B25: Travel | C25: Bus | D25: college bus | E25: 40 | F25: cash | G25: outside
A26: 46388 | B26: Entertainment | C26: Movie | E26: 350 | F26: card | G26: mall
A27: 46419 | B27: Food | E27: 90 | F27: cash | G27: outside
A28: 46447 | B28: food | C28: lunch | D28: canteen | E28: 200/- | F28: upi | G28: outside
A29: 46478 | B29: Food | C29: dinner | D29: zomato | E29: 280rs | F29: UPI | G29: home | H29: late
A30: 46508 | B30: Food | E30: 90 | F30: cash | G30: outside
A31: 46539 | B31: Travel | C31: Bus | D31: college bus | E31: 40 | F31: cash | G31: outside
A32: 46569 | B32: Entertainment | C32: Movie | E32: 350 | F32: card | G32: mall
A33: 46600 | B33: Food | E33: 90 | F33: cash | G33: outside
A34: 46631 | B34: Entertainment | C34: Movie | E34: 350 | F34: card | G34: mall
A35: 46661 | B35: Food | E35: 90 | F35: cash | G35: outside
A36: 46692 | B36: Travel | C36: Bus | D36: college bus | E36: 40 | F36: cash | G36: outside
A37: 46722 | B37: Entertainment | C37: Movie | E37: 350 | F37: card | G37: mall
A38: 46753 | B38: food | C38: lunch | D38: canteen | E38: 200/- | F38: upi | G38: outside
A39: 46784 | B39: Food | C39: dinner | D39: zomato | E39: 280rs | F39: UPI | G39: home | H39: late
A40: 46813 | B40: Food | E40: 90 | F40: cash | G40: outside
...

Sheet Cleaned_Data
A1: Date | B1: Category_Raw | C1: Category_Clean | D1: SubCategory_Raw | E1: SubCategory_Clean | F1: Description_Raw | G1: Description_Clean | H1: Amount_Raw | I1: Amount_Clean | J1: PaymentMode_Raw | K1: PaymentMode_Clean | L1: Location_Raw | M1: Location_Clean | N1: Remarks_Raw | O1: Remarks_Clean | P1: Month | Q1: Year | R1: Day | S1: Is_Weekend | T1: Expense_Level | U1: Payment_Flag | V1: Month_Number
A2: =DATE(2026, MONTH(Raw_Data!A2), DAY(Raw_Data!A2)) -> 46023 | B2: food | C2: =IF(LOWER(TRIM(B2))="food","Food",IF(LOWER(TRIM(B2))="travel","Travel",IF(LOWER(TRIM(B2))="entertainment","Entertainment","Other"))) -> Food | D2: lunch | E2: =IF(TRIM(D2)="","Not Specified", IF(C2="Food", IF(LOWER(D2)="lunch","Lunch", IF(LOWER(D2)="dinner","Dinner","Snacks")), IF(C2="Travel", IF(LOWER(D2)="bus","Bus","Bus"), IF(C2="Entertainment", IF(LOWER(D2)="movie","Movie","Other"), "Other")))) -> Lunch | F2: canteen | G2: =IF(TRIM(F2)="","Not Provided",PROPER(TRIM(F2))) -> Canteen | H2: 200/- | I2: =IF(H2="","",VALUE(SUBSTITUTE(SUBSTITUTE(SUBSTITUTE(LOWER(H2),"rs",""),"/-",""),"$",""))) -> 200 | J2: upi | K2: =IF(TRIM(J2)="","Not Specified",IF(LOWER(J2)="upi","UPI",IF(LOWER(J2)="cash","Cash",IF(LOWER(J2)="card","Card","Other")))) -> UPI | L2: outside | M2: =IF(TRIM(L2)="","Not Specified",PROPER(TRIM(L2))) -> Outside | O2: =IF(TRIM(N2)="","Not Specified",PROPER(TRIM(N2))) -> Not Specified | P2: =TEXT(Table1[[#This Row],[Date]],"mmmm") -> January | Q2: =YEAR(Table1[[#This Row],[Date]]) -> 2026 | R2: =TEXT(Table1[[#This Row],[Date]],"dddd") -> Thursday | S2: =IF(WEEKDAY(Table1[[#This Row],[Date]],2)>5,"Weekend","Weekday") -> Weekday | T2: =IF(Table1[[#This Row],[Amount_Clean]]>500,"High","Normal") -> Normal | U2: =IF(LOWER(TRIM(Table1[[#This Row],[PaymentMode_Clean]]))="cash","Cash","Digital") -> Digital | V2: =MONTH(Table1[[#This Row],[Date]]) -> 1
A3: =DATE(2026, MONTH(Raw_Data!A3), DAY(Raw_Data!A3)) -> 46054 | B3: Food | C3: =IF(LOWER(TRIM(B3))="food","Food",IF(LOWER(TRIM(B3))="travel","Travel",IF(LOWER(TRIM(B3))="entertainment","Entertainment","Other"))) -> Food | D3: dinner | E3: =IF(TRIM(D3)="","Not Specified", IF(C3="Food", IF(LOWER(D3)="lunch","Lunch", IF(LOWER(D3)="dinner","Dinner","Snacks")), IF(C3="Travel", IF(LOWER(D3)="bus","Bus","Bus"), IF(C3="Entertainment", IF(LOWER(D3)="movie","Movie","Other"), "Other")))) -> Dinner | F3: zomato | G3: =IF(TRIM(F3)="","Not Provided",PROPER(TRIM(F3))) -> Zomato | H3: 280rs | I3: =IF(H3="","",VALUE(SUBSTITUTE(SUBSTITUTE(SUBSTITUTE(LOWER(H3),"rs",""),"/-",""),"$",""))) -> 280 | J3: UPI | K3: =IF(TRIM(J3)="","Not Specified",IF(LOWER(J3)="upi","UPI",IF(LOWER(J3)="cash","Cash",IF(LOWER(J3)="card","Card","Other")))) -> UPI | L3: home | M3: =IF(TRIM(L3)="","Not Specified",PROPER(TRIM(L3))) -> Home | N3: late | O3: =IF(TRIM(N3)="","Not Specified",PROPER(TRIM(N3))) -> Late | P3: =TEXT(Table1[[#This Row],[Date]],"mmmm") -> February | Q3: =YEAR(Table1[[#This Row],[Date]]) -> 2026 | R3: =TEXT(Table1[[#This Row],[Date]],"dddd") -> Sunday | S3: =IF(WEEKDAY(Table1[[#This Row],[Date]],2)>5,"Weekend","Weekday") -> Weekend | T3: =IF(Table1[[#This Row],[Amount_Clean]]>500,"High","Normal") -> Normal | U3: =IF(LOWER(TRIM(Table1[[#This Row],[PaymentMode_Clean]]))="cash","Cash","Digital") -> Digital | V3: =MONTH(Table1[[#This Row],[Date]]) -> 2
A4: =DATE(2026, MONTH(Raw_Data!A4), DAY(Raw_Data!A4)) -> 46082 | B4: Food | C4: =IF(LOWER(TRIM(B4))="food","Food",IF(LOWER(TRIM(B4))="travel","Travel",IF(LOWER(TRIM(B4))="entertainment","Entertainment","Other"))) -> Food | E4: =IF(TRIM(D4)="","Not Specified", IF(C4="Food", IF(LOWER(D4)="lunch","Lunch", IF(LOWER(D4)="dinner","Dinner","Snacks")), IF(C4="Travel", IF(LOWER(D4)="bus","Bus","Bus"), IF(C4="Entertainment", IF(LOWER(D4)="movie","Movie","Other"), "Other")))) -> Not Specified | G4: =IF(TRIM(F4)="","Not Provided",PROPER(TRIM(F4))) -> Not Provided | H4: 90 | I4: =IF(H4="","",VALUE(SUBSTITUTE(SUBSTITUTE(SUBSTITUTE(LOWER(H4),"rs",""),"/-",""),"$",""))) -> 90 | J4: cash | K4: =IF(TRIM(J4)="","Not Specified",IF(LOWER(J4)="upi","UPI",IF(LOWER(J4)="cash","Cash",IF(LOWER(J4)="card","Card","Other")))) -> Cash | L4: outside | M4: =IF(TRIM(L4)="","Not Specified",PROPER(TRIM(L4))) -> Outside | O4: =IF(TRIM(N4)="","Not Specified",PROPER(TRIM(N4))) -> Not Specified | P4: =TEXT(Table1[[#This Row],[Date]],"mmmm") -> March | Q4: =YEAR(Table1[[#This Row],[Date]]) -> 2026 | R4: =TEXT(Table1[[#This Row],[Date]],"dddd") -> Sunday | S4: =IF(WEEKDAY(Table1[[#This Row],[Date]],2)>5,"Weekend","Weekday") -> Weekend | T4: =IF(Table1[[#This Row],[Amount_Clean]]>500,"High","Normal") -> Normal | U4: =IF(LOWER(TRIM(Table1[[#This Row],[PaymentMode_Clean]]))="cash","Cash","Digital") -> Cash | V4: =MONTH(Table1[[#This Row],[Date]]) -> 3
A5: =DATE(2026, MONTH(Raw_Data!A5), DAY(Raw_Data!A5)) -> 46113 | B5: Travel | C5: =IF(LOWER(TRIM(B5))="food","Food",IF(LOWER(TRIM(B5))="travel","Travel",IF(LOWER(TRIM(B5))="entertainment","Entertainment","Other"))) -> Travel | D5: Bus | E5: =IF(TRIM(D5)="","Not Specified", IF(C5="Food", IF(LOWER(D5)="lunch","Lunch", IF(LOWER(D5)="dinner","Dinner","Snacks")), IF(C5="Travel", IF(LOWER(D5)="bus","Bus","Bus"), IF(C5="Entertainment", IF(LOWER(D5)="movie","Movie","Other"), "Other")))) -> Bus | F5: college bus | G5: =IF(TRIM(F5)="","Not Provided",PROPER(TRIM(F5))) -> College Bus | H5: 40 | I5: =IF(H5="","",VALUE(SUBSTITUTE(SUBSTITUTE(SUBSTITUTE(LOWER(H5),"rs",""),"/-",""),"$",""))) -> 40 | J5: cash | K5: =IF(TRIM(J5)="","Not Specified",IF(LOWER(J5)="upi","UPI",IF(LOWER(J5)="cash","Cash",IF(LOWER(J5)="card","Card","Other")))) -> Cash | L5: outside | M5: =IF(TRIM(L5)="","Not Specified",PROPER(TRIM(L5))) -> Outside | O5: =IF(TRIM(N5)="","Not Specified",PROPER(TRIM(N5))) -> Not Specified | P5: =TEXT(Table1[[#This Row],[Date]],"mmmm") -> April | Q5: =YEAR(Table1[[#This Row],[Date]]) -> 2026 | R5: =TEXT(Table1[[#This Row],[Date]],"dddd") -> Wednesday | S5: =IF(WEEKDAY(Table1[[#This Row],[Date]],2)>5,"Weekend","Weekday") -> Weekday | T5: =IF(Table1[[#This Row],[Amount_Clean]]>500,"High","Normal") -> Normal | U5: =IF(LOWER(TRIM(Table1[[#This Row],[PaymentMode_Clean]]))="cash","Cash","Digital") -> Cash | V5: =MONTH(Table1[[#This Row],[Date]]) -> 4
A6: =DATE(2026, MONTH(Raw_Data!A6), DAY(Raw_Data!A6)) -> 46143 | B6: Entertainment | C6: =IF(LOWER(TRIM(B6))="food","Food",IF(LOWER(TRIM(B6))="travel","Travel",IF(LOWER(TRIM(B6))="entertainment","Entertainment","Other"))) -> Entertainment | D6: Movie | E6: =IF(TRIM(D6)="","Not Specified", IF(C6="Food", IF(LOWER(D6)="lunch","Lunch", IF(LOWER(D6)="dinner","Dinner","Snacks")), IF(C6="Travel", IF(LOWER(D6)="bus","Bus","Bus"), IF(C6="Entertainment", IF(LOWER(D6)="movie","Movie","Other"), "Other")))) -> Movie | G6: =IF(TRIM(F6)="","Not Provided",PROPER(TRIM(F6))) -> Not Provided | H6: 350 | I6: =IF(H6="","",VALUE(SUBSTITUTE(SUBSTITUTE(SUBSTITUTE(LOWER(H6),"rs",""),"/-",""),"$",""))) -> 350 | J6: card | K6: =IF(TRIM(J6)="","Not Specified",IF(LOWER(J6)="upi","UPI",IF(LOWER(J6)="cash","Cash",IF(LOWER(J6)="card","Card","Other")))) -> Card | L6: mall | M6: =IF(TRIM(L6)="","Not Specified",PROPER(TRIM(L6))) -> Mall | O6: =IF(TRIM(N6)="","Not Specified",PROPER(TRIM(N6))) -> Not Specified | P6: =TEXT(Table1[[#This Row],[Date]],"mmmm") -> May | Q6: =YEAR(Table1[[#This Row],[Date]]) -> 2026 | R6: =TEXT(Table1[[#This Row],[Date]],"dddd") -> Friday | S6: =IF(WEEKDAY(Table1[[#This Row],[Date]],2)>5,"Weekend","Weekday") -> Weekday | T6: =IF(Table1[[#This Row],[Amount_Clean]]>500,"High","Normal") -> Normal | U6: =IF(LOWER(TRIM(Table1[[#This Row],[PaymentMode_Clean]]))="cash","Cash","Digital") -> Digital | V6: =MONTH(Table1[[#This Row],[Date]]) -> 5
A7: =DATE(2026, MONTH(Raw_Data!A7), DAY(Raw_Data!A7)) -> 46174 | B7: Food | C7: =IF(LOWER(TRIM(B7))="food","Food",IF(LOWER(TRIM(B7))="travel","Travel",IF(LOWER(TRIM(B7))="entertainment","Entertainment","Other"))) -> Food | E7: =IF(TRIM(D7)="","Not Specified", IF(C7="Food", IF(LOWER(D7)="lunch","Lunch", IF(LOWER(D7)="dinner","Dinner","Snacks")), IF(C7="Travel", IF(LOWER(D7)="bus","Bus","Bus"), IF(C7="Entertainment", IF(LOWER(D7)="movie","Movie","Other"), "Other")))) -> Not Specified | G7: =IF(TRIM(F7)="","Not Provided",PROPER(TRIM(F7))) -> Not Provided | H7: 90 | I7: =IF(H7="","",VALUE(SUBSTITUTE(SUBSTITUTE(SUBSTITUTE(LOWER(H7),"rs",""),"/-",""),"$",""))) -> 90 | J7: cash | K7: =IF(TRIM(J7)="","Not Specified",IF(LOWER(J7)="upi","UPI",IF(LOWER(J7)="cash","Cash",IF(LOWER(J7)="card","Card","Other")))) -> Cash | L7: outside | M7: =IF(TRIM(L7)="","Not Specified",PROPER(TRIM(L7))) -> Outside | O7: =IF(TRIM(N7)="","Not Specified",PROPER(TRIM(N7))) -> Not Specified | P7: =TEXT(Table1[[#This Row],[Date]],"mmmm") -> June | Q7: =YEAR(Table1[[#This Row],[Date]]) -> 2026 | R7: =TEXT(Table1[[#This Row],[Date]],"dddd") -> Monday | S7: =IF(WEEKDAY(Table1[[#This Row],[Date]],2)>5,"Weekend","Weekday") -> Weekday | T7: =IF(Table1[[#This Row],[Amount_Clean]]>500,"High","Normal") -> Normal | U7: =IF(LOWER(TRIM(Table1[[#This Row],[PaymentMode_Clean]]))="cash","Cash","Digital") -> Cash | V7: =MONTH(Table1[[#This Row],[Date]]) -> 6
A8: =DATE(2026, MONTH(Raw_Data!A8), DAY(Raw_Data!A8)) -> 46204 | B8: Travel | C8: =IF(LOWER(TRIM(B8))="food","Food",IF(LOWER(TRIM(B8))="travel","Travel",IF(LOWER(TRIM(B8))="entertainment","Entertainment","Other"))) -> Travel | D8: Bus | E8: =IF(TRIM(D8)="","Not Specified", IF(C8="Food", IF(LOWER(D8)="lunch","Lunch", IF(LOWER(D8)="dinner","Dinner","Snacks")), IF(C8="Travel", IF(LOWER(D8)="bus","Bus","Bus"), IF(C8="Entertainment", IF(LOWER(D8)="movie","Movie","Other"), "Other")))) -> Bus | F8: college bus | G8: =IF(TRIM(F8)="","Not Provided",PROPER(TRIM(F8))) -> College Bus | H8: 40 | I8: =IF(H8="","",VALUE(SUBSTITUTE(SUBSTITUTE(SUBSTITUTE(LOWER(H8),"rs",""),"/-",""),"$",""))) -> 40 | J8: cash | K8: =IF(TRIM(J8)="","Not Specified",IF(LOWER(J8)="upi","UPI",IF(LOWER(J8)="cash","Cash",IF(LOWER(J8)="card","Card","Other")))) -> Cash | L8: outside | M8: =IF(TRIM(L8)="","Not Specified",PROPER(TRIM(L8))) -> Outside | O8: =IF(TRIM(N8)="","Not Specified",PROPER(TRIM(N8))) -> Not Specified | P8: =TEXT(Table1[[#This Row],[Date]],"mmmm") -> July | Q8: =YEAR(Table1[[#This Row],[Date]]) -> 2026 | R8: =TEXT(Table1[[#This Row],[Date]],"dddd") -> Wednesday | S8: =IF(WEEKDAY(Table1[[#This Row],[Date]],2)>5,"Weekend","Weekday") -> Weekday | T8: =IF(Table1[[#This Row],[Amount_Clean]]>500,"High","Normal") -> Normal | U8: =IF(LOWER(TRIM(Table1[[#This Row],[PaymentMode_Clean]]))="cash","Cash","Digital") -> Cash | V8: =MONTH(Table1[[#This Row],[Date]]) -> 7
A9: =DATE(2026, MONTH(Raw_Data!A9), DAY(Raw_Data!A9)) -> 46235 | B9: Entertainment | C9: =IF(LOWER(TRIM(B9))="food","Food",IF(LOWER(TRIM(B9))="travel","Travel",IF(LOWER(TRIM(B9))="entertainment","Entertainment","Other"))) -> Entertainment | D9: Movie | E9: =IF(TRIM(D9)="","Not Specified", IF(C9="Food", IF(LOWER(D9)="lunch","Lunch", IF(LOWER(D9)="dinner","Dinner","Snacks")), IF(C9="Travel", IF(LOWER(D9)="bus","Bus","Bus"), IF(C9="Entertainment", IF(LOWER(D9)="movie","Movie","Other"), "Other")))) -> Movie | G9: =IF(TRIM(F9)="","Not Provided",PROPER(TRIM(F9))) -> Not Provided | H9: 350 | I9: =IF(H9="","",VALUE(SUBSTITUTE(SUBSTITUTE(SUBSTITUTE(LOWER(H9),"rs",""),"/-",""),"$",""))) -> 350 | J9: card | K9: =IF(TRIM(J9)="","Not Specified",IF(LOWER(J9)="upi","UPI",IF(LOWER(J9)="cash","Cash",IF(LOWER(J9)="card","Card","Other")))) -> Card | L9: mall | M9: =IF(TRIM(L9)="","Not Specified",PROPER(TRIM(L9))) -> Mall | O9: =IF(TRIM(N9)="","Not Specified",PROPER(TRIM(N9))) -> Not Specified | P9: =TEXT(Table1[[#This Row],[Date]],"mmmm") -> August | Q9: =YEAR(Table1[[#This Row],[Date]]) -> 2026 | R9: =TEXT(Table1[[#This Row],[Date]],"dddd") -> Saturday | S9: =IF(WEEKDAY(Table1[[#This Row],[Date]],2)>5,"Weekend","Weekday") -> Weekend | T9: =IF(Table1[[#This Row],[Amount_Clean]]>500,"High","Normal") -> Normal | U9: =IF(LOWER(TRIM(Table1[[#This Row],[PaymentMode_Clean]]))="cash","Cash","Digital") -> Digital | V9: =MONTH(Table1[[#This Row],[Date]]) -> 8
A10: =DATE(2026, MONTH(Raw_Data!A10), DAY(Raw_Data!A10)) -> 46266 | B10: food | C10: =IF(LOWER(TRIM(B10))="food","Food",IF(LOWER(TRIM(B10))="travel","Travel",IF(LOWER(TRIM(B10))="entertainment","Entertainment","Other"))) -> Food | D10: lunch | E10: =IF(TRIM(D10)="","Not Specified", IF(C10="Food", IF(LOWER(D10)="lunch","Lunch", IF(LOWER(D10)="dinner","Dinner","Snacks")), IF(C10="Travel", IF(LOWER(D10)="bus","Bus","Bus"), IF(C10="Entertainment", IF(LOWER(D10)="movie","Movie","Other"), "Other")))) -> Lunch | F10: canteen | G10: =IF(TRIM(F10)="","Not Provided",PROPER(TRIM(F10))) -> Canteen | H10: 200/- | I10: =IF(H10="","",VALUE(SUBSTITUTE(SUBSTITUTE(SUBSTITUTE(LOWER(H10),"rs",""),"/-",""),"$",""))) -> 200 | J10: upi | K10: =IF(TRIM(J10)="","Not Specified",IF(LOWER(J10)="upi","UPI",IF(LOWER(J10)="cash","Cash",IF(LOWER(J10)="card","Card","Other")))) -> UPI | L10: outside | M10: =IF(TRIM(L10)="","Not Specified",PROPER(TRIM(L10))) -> Outside | O10: =IF(TRIM(N10)="","Not Specified",PROPER(TRIM(N10))) -> Not Specified | P10: =TEXT(Table1[[#This Row],[Date]],"mmmm") -> September | Q10: =YEAR(Table1[[#This Row],[Date]]) -> 2026 | R10: =TEXT(Table1[[#This Row],[Date]],"dddd") -> Tuesday | S10: =IF(WEEKDAY(Table1[[#This Row],[Date]],2)>5,"Weekend","Weekday") -> Weekday | T10: =IF(Table1[[#This Row],[Amount_Clean]]>500,"High","Normal") -> Normal | U10: =IF(LOWER(TRIM(Table1[[#This Row],[PaymentMode_Clean]]))="cash","Cash","Digital") -> Digital | V10: =MONTH(Table1[[#This Row],[Date]]) -> 9
A11: =DATE(2026, MONTH(Raw_Data!A11), DAY(Raw_Data!A11)) -> 46296 | B11: Food | C11: =IF(LOWER(TRIM(B11))="food","Food",IF(LOWER(TRIM(B11))="travel","Travel",IF(LOWER(TRIM(B11))="entertainment","Entertainment","Other"))) -> Food | D11: dinner | E11: =IF(TRIM(D11)="","Not Specified", IF(C11="Food", IF(LOWER(D11)="lunch","Lunch", IF(LOWER(D11)="dinner","Dinner","Snacks")), IF(C11="Travel", IF(LOWER(D11)="bus","Bus","Bus"), IF(C11="Entertainment", IF(LOWER(D11)="movie","Movie","Other"), "Other")))) -> Dinner | F11: zomato | G11: =IF(TRIM(F11)="","Not Provided",PROPER(TRIM(F11))) -> Zomato | H11: 280rs | I11: =IF(H11="","",VALUE(SUBSTITUTE(SUBSTITUTE(SUBSTITUTE(LOWER(H11),"rs",""),"/-",""),"$",""))) -> 280 | J11: UPI | K11: =IF(TRIM(J11)="","Not Specified",IF(LOWER(J11)="upi","UPI",IF(LOWER(J11)="cash","Cash",IF(LOWER(J11)="card","Card","Other")))) -> UPI | L11: home | M11: =IF(TRIM(L11)="","Not Specified",PROPER(TRIM(L11))) -> Home | N11: late | O11: =IF(TRIM(N11)="","Not Specified",PROPER(TRIM(N11))) -> Late | P11: =TEXT(Table1[[#This Row],[Date]],"mmmm") -> October | Q11: =YEAR(Table1[[#This Row],[Date]]) -> 2026 | R11: =TEXT(Table1[[#This Row],[Date]],"dddd") -> Thursday | S11: =IF(WEEKDAY(Table1[[#This Row],[Date]],2)>5,"Weekend","Weekday") -> Weekday | T11: =IF(Table1[[#This Row],[Amount_Clean]]>500,"High","Normal") -> Normal | U11: =IF(LOWER(TRIM(Table1[[#This Row],[PaymentMode_Clean]]))="cash","Cash","Digital") -> Digital | V11: =MONTH(Table1[[#This Row],[Date]]) -> 10
A12: =DATE(2026, MONTH(Raw_Data!A12), DAY(Raw_Data!A12)) -> 46327 | B12: Food | C12: =IF(LOWER(TRIM(B12))="food","Food",IF(LOWER(TRIM(B12))="travel","Travel",IF(LOWER(TRIM(B12))="entertainment","Entertainment","Other"))) -> Food | E12: =IF(TRIM(D12)="","Not Specified", IF(C12="Food", IF(LOWER(D12)="lunch","Lunch", IF(LOWER(D12)="dinner","Dinner","Snacks")), IF(C12="Travel", IF(LOWER(D12)="bus","Bus","Bus"), IF(C12="Entertainment", IF(LOWER(D12)="movie","Movie","Other"), "Other")))) -> Not Specified | G12: =IF(TRIM(F12)="","Not Provided",PROPER(TRIM(F12))) -> Not Provided | H12: 90 | I12: =IF(H12="","",VALUE(SUBSTITUTE(SUBSTITUTE(SUBSTITUTE(LOWER(H12),"rs",""),"/-",""),"$",""))) -> 90 | J12: cash | K12: =IF(TRIM(J12)="","Not Specified",IF(LOWER(J12)="upi","UPI",IF(LOWER(J12)="cash","Cash",IF(LOWER(J12)="card","Card","Other")))) -> Cash | L12: outside | M12: =IF(TRIM(L12)="","Not Specified",PROPER(TRIM(L12))) -> Outside | O12: =IF(TRIM(N12)="","Not Specified",PROPER(TRIM(N12))) -> Not Specified | P12: =TEXT(Table1[[#This Row],[Date]],"mmmm") -> November | Q12: =YEAR(Table1[[#This Row],[Date]]) -> 2026 | R12: =TEXT(Table1[[#This Row],[Date]],"dddd") -> Sunday | S12: =IF(WEEKDAY(Table1[[#This Row],[Date]],2)>5,"Weekend","Weekday") -> Weekend | T12: =IF(Table1[[#This Row],[Amount_Clean]]>500,"High","Normal") -> Normal | U12: =IF(LOWER(TRIM(Table1[[#This Row],[PaymentMode_Clean]]))="cash","Cash","Digital") -> Cash | V12: =MONTH(Table1[[#This Row],[Date]]) -> 11
A13: =DATE(2026, MONTH(Raw_Data!A13), DAY(Raw_Data!A13)) -> 46357 | B13: Food | C13: =IF(LOWER(TRIM(B13))="food","Food",IF(LOWER(TRIM(B13))="travel","Travel",IF(LOWER(TRIM(B13))="entertainment","Entertainment","Other"))) -> Food | D13: dinner | E13: =IF(TRIM(D13)="","Not Specified", IF(C13="Food", IF(LOWER(D13)="lunch","Lunch", IF(LOWER(D13)="dinner","Dinner","Snacks")), IF(C13="Travel", IF(LOWER(D13)="bus","Bus","Bus"), IF(C13="Entertainment", IF(LOWER(D13)="movie","Movie","Other"), "Other")))) -> Dinner | F13: zomato | G13: =IF(TRIM(F13)="","Not Provided",PROPER(TRIM(F13))) -> Zomato | H13: 280rs | I13: =IF(H13="","",VALUE(SUBSTITUTE(SUBSTITUTE(SUBSTITUTE(LOWER(H13),"rs",""),"/-",""),"$",""))) -> 280 | J13: UPI | K13: =IF(TRIM(J13)="","Not Specified",IF(LOWER(J13)="upi","UPI",IF(LOWER(J13)="cash","Cash",IF(LOWER(J13)="card","Card","Other")))) -> UPI | L13: home | M13: =IF(TRIM(L13)="","Not Specified",PROPER(TRIM(L13))) -> Home | N13: late | O13: =IF(TRIM(N13)="","Not Specified",PROPER(TRIM(N13))) -> Late | P13: =TEXT(Table1[[#This Row],[Date]],"mmmm") -> December | Q13: =YEAR(Table1[[#This Row],[Date]]) -> 2026 | R13: =TEXT(Table1[[#This Row],[Date]],"dddd") -> Tuesday | S13: =IF(WEEKDAY(Table1[[#This Row],[Date]],2)>5,"Weekend","Weekday") -> Weekday | T13: =IF(Table1[[#This Row],[Amount_Clean]]>500,"High","Normal") -> Normal | U13: =IF(LOWER(TRIM(Table1[[#This Row],[PaymentMode_Clean]]))="cash","Cash","Digital") -> Digital | V13: =MONTH(Table1[[#This Row],[Date]]) -> 12
A14: =DATE(2026, MONTH(Raw_Data!A14), DAY(Raw_Data!A14)) -> 46023 | B14: Food | C14: =IF(LOWER(TRIM(B14))="food","Food",IF(LOWER(TRIM(B14))="travel","Travel",IF(LOWER(TRIM(B14))="entertainment","Entertainment","Other"))) -> Food | E14: =IF(TRIM(D14)="","Not Specified", IF(C14="Food", IF(LOWER(D14)="lunch","Lunch", IF(LOWER(D14)="dinner","Dinner","Snacks")), IF(C14="Travel", IF(LOWER(D14)="bus","Bus","Bus"), IF(C14="Entertainment", IF(LOWER(D14)="movie","Movie","Other"), "Other")))) -> Not Specified | G14: =IF(TRIM(F14)="","Not Provided",PROPER(TRIM(F14))) -> Not Provided | H14: 90 | I14: =IF(H14="","",VALUE(SUBSTITUTE(SUBSTITUTE(SUBSTITUTE(LOWER(H14),"rs",""),"/-",""),"$",""))) -> 90 | J14: cash | K14: =IF(TRIM(J14)="","Not Specified",IF(LOWER(J14)="upi","UPI",IF(LOWER(J14)="cash","Cash",IF(LOWER(J14)="card","Card","Other")))) -> Cash | L14: outside | M14: =IF(TRIM(L14)="","Not Specified",PROPER(TRIM(L14))) -> Outside | O14: =IF(TRIM(N14)="","Not Specified",PROPER(TRIM(N14))) -> Not Specified | P14: =TEXT(Table1[[#This Row],[Date]],"mmmm") -> January | Q14: =YEAR(Table1[[#This Row],[Date]]) -> 2026 | R14: =TEXT(Table1[[#This Row],[Date]],"dddd") -> Thursday | S14: =IF(WEEKDAY(Table1[[#This Row],[Date]],2)>5,"Weekend","Weekday") -> Weekday | T14: =IF(Table1[[#This Row],[Amount_Clean]]>500,"High","Normal") -> Normal | U14: =IF(LOWER(TRIM(Table1[[#This Row],[PaymentMode_Clean]]))="cash","Cash","Digital") -> Cash | V14: =MONTH(Table1[[#This Row],[Date]]) -> 1
A15: =DATE(2026, MONTH(Raw_Data!A15), DAY(Raw_Data!A15)) -> 46054 | B15: Travel | C15: =IF(LOWER(TRIM(B15))="food","Food",IF(LOWER(TRIM(B15))="travel","Travel",IF(LOWER(TRIM(B15))="entertainment","Entertainment","Other"))) -> Travel | D15: Bus | E15: =IF(TRIM(D15)="","Not Specified", IF(C15="Food", IF(LOWER(D15)="lunch","Lunch", IF(LOWER(D15)="dinner","Dinner","Snacks")), IF(C15="Travel", IF(LOWER(D15)="bus","Bus","Bus"), IF(C15="Entertainment", IF(LOWER(D15)="movie","Movie","Other"), "Other")))) -> Bus | F15: college bus | G15: =IF(TRIM(F15)="","Not Provided",PROPER(TRIM(F15))) -> College Bus | H15: 40 | I15: =IF(H15="","",VALUE(SUBSTITUTE(SUBSTITUTE(SUBSTITUTE(LOWER(H15),"rs",""),"/-",""),"$",""))) -> 40 | J15: cash | K15: =IF(TRIM(J15)="","Not Specified",IF(LOWER(J15)="upi","UPI",IF(LOWER(J15)="cash","Cash",IF(LOWER(J15)="card","Card","Other")))) -> Cash | L15: outside | M15: =IF(TRIM(L15)="","Not Specified",PROPER(TRIM(L15))) -> Outside | O15: =IF(TRIM(N15)="","Not Specified",PROPER(TRIM(N15))) -> Not Specified | P15: =TEXT(Table1[[#This Row],[Date]],"mmmm") -> February | Q15: =YEAR(Table1[[#This Row],[Date]]) -> 2026 | R15: =TEXT(Table1[[#This Row],[Date]],"dddd") -> Sunday | S15: =IF(WEEKDAY(Table1[[#This Row],[Date]],2)>5,"Weekend","Weekday") -> Weekend | T15: =IF(Table1[[#This Row],[Amount_Clean]]>500,"High","Normal") -> Normal | U15: =IF(LOWER(TRIM(Table1[[#This Row],[PaymentMode_Clean]]))="cash","Cash","Digital") -> Cash | V15: =MONTH(Table1[[#This Row],[Date]]) -> 2
A16: =DATE(2026, MONTH(Raw_Data!A16), DAY(Raw_Data!A16)) -> 46082 | B16: Entertainment | C16: =IF(LOWER(TRIM(B16))="food","Food",IF(LOWER(TRIM(B16))="travel","Travel",IF(LOWER(TRIM(B16))="entertainment","Entertainment","Other"))) -> Entertainment | D16: Movie | E16: =IF(TRIM(D16)="","Not Specified", IF(C16="Food", IF(LOWER(D16)="lunch","Lunch", IF(LOWER(D16)="dinner","Dinner","Snacks")), IF(C16="Travel", IF(LOWER(D16)="bus","Bus","Bus"), IF(C16="Entertainment", IF(LOWER(D16)="movie","Movie","Other"), "Other")))) -> Movie | G16: =IF(TRIM(F16)="","Not Provided",PROPER(TRIM(F16))) -> Not Provided | H16: 350 | I16: =IF(H16="","",VALUE(SUBSTITUTE(SUBSTITUTE(SUBSTITUTE(LOWER(H16),"rs",""),"/-",""),"$",""))) -> 350 | J16: card | K16: =IF(TRIM(J16)="","Not Specified",IF(LOWER(J16)="upi","UPI",IF(LOWER(J16)="cash","Cash",IF(LOWER(J16)="card","Card","Other")))) -> Card | L16: mall | M16: =IF(TRIM(L16)="","Not Specified",PROPER(TRIM(L16))) -> Mall | O16: =IF(TRIM(N16)="","Not Specified",PROPER(TRIM(N16))) -> Not Specified | P16: =TEXT(Table1[[#This Row],[Date]],"mmmm") -> March | Q16: =YEAR(Table1[[#This Row],[Date]]) -> 2026 | R16: =TEXT(Table1[[#This Row],[Date]],"dddd") -> Sunday | S16: =IF(WEEKDAY(Table1[[#This Row],[Date]],2)>5,"Weekend","Weekday") -> Weekend | T16: =IF(Table1[[#This Row],[Amount_Clean]]>500,"High","Normal") -> Normal | U16: =IF(LOWER(TRIM(Table1[[#This Row],[PaymentMode_Clean]]))="cash","Cash","Digital") -> Digital | V16: =MONTH(Table1[[#This Row],[Date]]) -> 3
A17: =DATE(2026, MONTH(Raw_Data!A17), DAY(Raw_Data!A17)) -> 46113 | B17: Food | C17: =IF(LOWER(TRIM(B17))="food","Food",IF(LOWER(TRIM(B17))="travel","Travel",IF(LOWER(TRIM(B17))="entertainment","Entertainment","Other"))) -> Food | E17: =IF(TRIM(D17)="","Not Specified", IF(C17="Food", IF(LOWER(D17)="lunch","Lunch", IF(LOWER(D17)="dinner","Dinner","Snacks")), IF(C17="Travel", IF(LOWER(D17)="bus","Bus","Bus"), IF(C17="Entertainment", IF(LOWER(D17)="movie","Movie","Other"), "Other")))) -> Not Specified | G17: =IF(TRIM(F17)="","Not Provided",PROPER(TRIM(F17))) -> Not Provided | H17: 90 | I17: =IF(H17="","",VALUE(SUBSTITUTE(SUBSTITUTE(SUBSTITUTE(LOWER(H17),"rs",""),"/-",""),"$",""))) -> 90 | J17: cash | K17: =IF(TRIM(J17)="","Not Specified",IF(LOWER(J17)="upi","UPI",IF(LOWER(J17)="cash","Cash",IF(LOWER(J17)="card","Card","Other")))) -> Cash | L17: outside | M17: =IF(TRIM(L17)="","Not Specified",PROPER(TRIM(L17))) -> Outside | O17: =IF(TRIM(N17)="","Not Specified",PROPER(TRIM(N17))) -> Not Specified | P17: =TEXT(Table1[[#This Row],[Date]],"mmmm") -> April | Q17: =YEAR(Table1[[#This Row],[Date]]) -> 2026 | R17: =TEXT(Table1[[#This Row],[Date]],"dddd") -> Wednesday | S17: =IF(WEEKDAY(Table1[[#This Row],[Date]],2)>5,"Weekend","Weekday") -> Weekday | T17: =IF(Table1[[#This Row],[Amount_Clean]]>500,"High","Normal") -> Normal | U17: =IF(LOWER(TRIM(Table1[[#This Row],[PaymentMode_Clean]]))="cash","Cash","Digital") -> Cash | V17: =MONTH(Table1[[#This Row],[Date]]) -> 4
A18: =DATE(2026, MONTH(Raw_Data!A18), DAY(Raw_Data!A18)) -> 46143 | B18: Travel | C18: =IF(LOWER(TRIM(B18))="food","Food",IF(LOWER(TRIM(B18))="travel","Travel",IF(LOWER(TRIM(B18))="entertainment","Entertainment","Other"))) -> Travel | D18: Bus | E18: =IF(TRIM(D18)="","Not Specified", IF(C18="Food", IF(LOWER(D18)="lunch","Lunch", IF(LOWER(D18)="dinner","Dinner","Snacks")), IF(C18="Travel", IF(LOWER(D18)="bus","Bus","Bus"), IF(C18="Entertainment", IF(LOWER(D18)="movie","Movie","Other"), "Other")))) -> Bus | F18: college bus | G18: =IF(TRIM(F18)="","Not Provided",PROPER(TRIM(F18))) -> College Bus | H18: 40 | I18: =IF(H18="","",VALUE(SUBSTITUTE(SUBSTITUTE(SUBSTITUTE(LOWER(H18),"rs",""),"/-",""),"$",""))) -> 40 | J18: cash | K18: =IF(TRIM(J18)="","Not Specified",IF(LOWER(J18)="upi","UPI",IF(LOWER(J18)="cash","Cash",IF(LOWER(J18)="card","Card","Other")))) -> Cash | L18: outside | M18: =IF(TRIM(L18)="","Not Specified",PROPER(TRIM(L18))) -> Outside | O18: =IF(TRIM(N18)="","Not Specified",PROPER(TRIM(N18))) -> Not Specified | P18: =TEXT(Table1[[#This Row],[Date]],"mmmm") -> May | Q18: =YEAR(Table1[[#This Row],[Date]]) -> 2026 | R18: =TEXT(Table1[[#This Row],[Date]],"dddd") -> Friday | S18: =IF(WEEKDAY(Table1[[#This Row],[Date]],2)>5,"Weekend","Weekday") -> Weekday | T18: =IF(Table1[[#This Row],[Amount_Clean]]>500,"High","Normal") -> Normal | U18: =IF(LOWER(TRIM(Table1[[#This Row],[PaymentMode_Clean]]))="cash","Cash","Digital") -> Cash | V18: =MONTH(Table1[[#This Row],[Date]]) -> 5
A19: =DATE(2026, MONTH(Raw_Data!A19), DAY(Raw_Data!A19)) -> 46174 | B19: Entertainment | C19: =IF(LOWER(TRIM(B19))="food","Food",IF(LOWER(TRIM(B19))="travel","Travel",IF(LOWER(TRIM(B19))="entertainment","Entertainment","Other"))) -> Entertainment | D19: Movie | E19: =IF(TRIM(D19)="","Not Specified", IF(C19="Food", IF(LOWER(D19)="lunch","Lunch", IF(LOWER(D19)="dinner","Dinner","Snacks")), IF(C19="Travel", IF(LOWER(D19)="bus","Bus","Bus"), IF(C19="Entertainment", IF(LOWER(D19)="movie","Movie","Other"), "Other")))) -> Movie | G19: =IF(TRIM(F19)="","Not Provided",PROPER(TRIM(F19))) -> Not Provided | H19: 350 | I19: =IF(H19="","",VALUE(SUBSTITUTE(SUBSTITUTE(SUBSTITUTE(LOWER(H19),"rs",""),"/-",""),"$",""))) -> 350 | J19: card | K19: =IF(TRIM(J19)="","Not Specified",IF(LOWER(J19)="upi","UPI",IF(LOWER(J19)="cash","Cash",IF(LOWER(J19)="card","Card","Other")))) -> Card | L19: mall | M19: =IF(TRIM(L19)="","Not Specified",PROPER(TRIM(L19))) -> Mall | O19: =IF(TRIM(N19)="","Not Specified",PROPER(TRIM(N19))) -> Not Specified | P19: =TEXT(Table1[[#This Row],[Date]],"mmmm") -> June | Q19: =YEAR(Table1[[#This Row],[Date]]) -> 2026 | R19: =TEXT(Table1[[#This Row],[Date]],"dddd") -> Monday | S19: =IF(WEEKDAY(Table1[[#This Row],[Date]],2)>5,"Weekend","Weekday") -> Weekday | T19: =IF(Table1[[#This Row],[Amount_Clean]]>500,"High","Normal") -> Normal | U19: =IF(LOWER(TRIM(Table1[[#This Row],[PaymentMode_Clean]]))="cash","Cash","Digital") -> Digital | V19: =MONTH(Table1[[#This Row],[Date]]) -> 6
A20: =DATE(2026, MONTH(Raw_Data!A20), DAY(Raw_Data!A20)) -> 46204 | B20: Entertainment | C20: =IF(LOWER(TRIM(B20))="food","Food",IF(LOWER(TRIM(B20))="travel","Travel",IF(LOWER(TRIM(B20))="entertainment","Entertainment","Other"))) -> Entertainment | D20: Movie | E20: =IF(TRIM(D20)="","Not Specified", IF(C20="Food", IF(LOWER(D20)="lunch","Lunch", IF(LOWER(D20)="dinner","Dinner","Snacks")), IF(C20="Travel", IF(LOWER(D20)="bus","Bus","Bus"), IF(C20="Entertainment", IF(LOWER(D20)="movie","Movie","Other"), "Other")))) -> Movie | G20: =IF(TRIM(F20)="","Not Provided",PROPER(TRIM(F20))) -> Not Provided | H20: 350 | I20: =IF(H20="","",VALUE(SUBSTITUTE(SUBSTITUTE(SUBSTITUTE(LOWER(H20),"rs",""),"/-",""),"$",""))) -> 350 | J20: card | K20: =IF(TRIM(J20)="","Not Specified",IF(LOWER(J20)="upi","UPI",IF(LOWER(J20)="cash","Cash",IF(LOWER(J20)="card","Card","Other")))) -> Card | L20: mall | M20: =IF(TRIM(L20)="","Not Specified",PROPER(TRIM(L20))) -> Mall | O20: =IF(TRIM(N20)="","Not Specified",PROPER(TRIM(N20))) -> Not Specified | P20: =TEXT(Table1[[#This Row],[Date]],"mmmm") -> July | Q20: =YEAR(Table1[[#This Row],[Date]]) -> 2026 | R20: =TEXT(Table1[[#This Row],[Date]],"dddd") -> Wednesday | S20: =IF(WEEKDAY(Table1[[#This Row],[Date]],2)>5,"Weekend","Weekday") -> Weekday | T20: =IF(Table1[[#This Row],[Amount_Clean]]>500,"High","Normal") -> Normal | U20: =IF(LOWER(TRIM(Table1[[#This Row],[PaymentMode_Clean]]))="cash","Cash","Digital") -> Digital | V20: =MONTH(Table1[[#This Row],[Date]]) -> 7
A21: =DATE(2026, MONTH(Raw_Data!A21), DAY(Raw_Data!A21)) -> 46235 | B21: Food | C21: =IF(LOWER(TRIM(B21))="food","Food",IF(LOWER(TRIM(B21))="travel","Travel",IF(LOWER(TRIM(B21))="entertainment","Entertainment","Other"))) -> Food | E21: =IF(TRIM(D21)="","Not Specified", IF(C21="Food", IF(LOWER(D21)="lunch","Lunch", IF(LOWER(D21)="dinner","Dinner","Snacks")), IF(C21="Travel", IF(LOWER(D21)="bus","Bus","Bus"), IF(C21="Entertainment", IF(LOWER(D21)="movie","Movie","Other"), "Other")))) -> Not Specified | G21: =IF(TRIM(F21)="","Not Provided",PROPER(TRIM(F21))) -> Not Provided | H21: 90 | I21: =IF(H21="","",VALUE(SUBSTITUTE(SUBSTITUTE(SUBSTITUTE(LOWER(H21),"rs",""),"/-",""),"$",""))) -> 90 | J21: cash | K21: =IF(TRIM(J21)="","Not Specified",IF(LOWER(J21)="upi","UPI",IF(LOWER(J21)="cash","Cash",IF(LOWER(J21)="card","Card","Other")))) -> Cash | L21: outside | M21: =IF(TRIM(L21)="","Not Specified",PROPER(TRIM(L21))) -> Outside | O21: =IF(TRIM(N21)="","Not Specified",PROPER(TRIM(N21))) -> Not Specified | P21: =TEXT(Table1[[#This Row],[Date]],"mmmm") -> August | Q21: =YEAR(Table1[[#This Row],[Date]]) -> 2026 | R21: =TEXT(Table1[[#This Row],[Date]],"dddd") -> Saturday | S21: =IF(WEEKDAY(Table1[[#This Row],[Date]],2)>5,"Weekend","Weekday") -> Weekend | T21: =IF(Table1[[#This Row],[Amount_Clean]]>500,"High","Normal") -> Normal | U21: =IF(LOWER(TRIM(Table1[[#This Row],[PaymentMode_Clean]]))="cash","Cash","Digital") -> Cash | V21: =MONTH(Table1[[#This Row],[Date]]) -> 8
A22: =DATE(2026, MONTH(Raw_Data!A22), DAY(Raw_Data!A22)) -> 46266 | B22: food | C22: =IF(LOWER(TRIM(B22))="food","Food",IF(LOWER(TRIM(B22))="travel","Travel",IF(LOWER(TRIM(B22))="entertainment","Entertainment","Other"))) -> Food | D22: lunch | E22: =IF(TRIM(D22)="","Not Specified", IF(C22="Food", IF(LOWER(D22)="lunch","Lunch", IF(LOWER(D22)="dinner","Dinner","Snacks")), IF(C22="Travel", IF(LOWER(D22)="bus","Bus","Bus"), IF(C22="Entertainment", IF(LOWER(D22)="movie","Movie","Other"), "Other")))) -> Lunch | F22: canteen | G22: =IF(TRIM(F22)="","Not Provided",PROPER(TRIM(F22))) -> Canteen | H22: 200/- | I22: =IF(H22="","",VALUE(SUBSTITUTE(SUBSTITUTE(SUBSTITUTE(LOWER(H22),"rs",""),"/-",""),"$",""))) -> 200 | J22: upi | K22: =IF(TRIM(J22)="","Not Specified",IF(LOWER(J22)="upi","UPI",IF(LOWER(J22)="cash","Cash",IF(LOWER(J22)="card","Card","Other")))) -> UPI | L22: outside | M22: =IF(TRIM(L22)="","Not Specified",PROPER(TRIM(L22))) -> Outside | O22: =IF(TRIM(N22)="","Not Specified",PROPER(TRIM(N22))) -> Not Specified | P22: =TEXT(Table1[[#This Row],[Date]],"mmmm") -> September | Q22: =YEAR(Table1[[#This Row],[Date]]) -> 2026 | R22: =TEXT(Table1[[#This Row],[Date]],"dddd") -> Tuesday | S22: =IF(WEEKDAY(Table1[[#This Row],[Date]],2)>5,"Weekend","Weekday") -> Weekday | T22: =IF(Table1[[#This Row],[Amount_Clean]]>500,"High","Normal") -> Normal | U22: =IF(LOWER(TRIM(Table1[[#This Row],[PaymentMode_Clean]]))="cash","Cash","Digital") -> Digital | V22: =MONTH(Table1[[#This Row],[Date]]) -> 9
A23: =DATE(2026, MONTH(Raw_Data!A23), DAY(Raw_Data!A23)) -> 46296 | B23: Food | C23: =IF(LOWER(TRIM(B23))="food","Food",IF(LOWER(TRIM(B23))="travel","Travel",IF(LOWER(TRIM(B23))="entertainment","Entertainment","Other"))) -> Food | D23: dinner | E23: =IF(TRIM(D23)="","Not Specified", IF(C23="Food", IF(LOWER(D23)="lunch","Lunch", IF(LOWER(D23)="dinner","Dinner","Snacks")), IF(C23="Travel", IF(LOWER(D23)="bus","Bus","Bus"), IF(C23="Entertainment", IF(LOWER(D23)="movie","Movie","Other"), "Other")))) -> Dinner | F23: zomato | G23: =IF(TRIM(F23)="","Not Provided",PROPER(TRIM(F23))) -> Zomato | H23: 280rs | I23: =IF(H23="","",VALUE(SUBSTITUTE(SUBSTITUTE(SUBSTITUTE(LOWER(H23),"rs",""),"/-",""),"$",""))) -> 280 | J23: UPI | K23: =IF(TRIM(J23)="","Not Specified",IF(LOWER(J23)="upi","UPI",IF(LOWER(J23)="cash","Cash",IF(LOWER(J23)="card","Card","Other")))) -> UPI | L23: home | M23: =IF(TRIM(L23)="","Not Specified",PROPER(TRIM(L23))) -> Home | N23: late | O23: =IF(TRIM(N23)="","Not Specified",PROPER(TRIM(N23))) -> Late | P23: =TEXT(Table1[[#This Row],[Date]],"mmmm") -> October | Q23: =YEAR(Table1[[#This Row],[Date]]) -> 2026 | R23: =TEXT(Table1[[#This Row],[Date]],"dddd") -> Thursday | S23: =IF(WEEKDAY(Table1[[#This Row],[Date]],2)>5,"Weekend","Weekday") -> Weekday | T23: =IF(Table1[[#This Row],[Amount_Clean]]>500,"High","Normal") -> Normal | U23: =IF(LOWER(TRIM(Table1[[#This Row],[PaymentMode_Clean]]))="cash","Cash","Digital") -> Digital | V23: =MONTH(Table1[[#This Row],[Date]]) -> 10
A24: =DATE(2026, MONTH(Raw_Data!A24), DAY(Raw_Data!A24)) -> 46327 | B24: Food | C24: =IF(LOWER(TRIM(B24))="food","Food",IF(LOWER(TRIM(B24))="travel","Travel",IF(LOWER(TRIM(B24))="entertainment","Entertainment","Other"))) -> Food | E24: =IF(TRIM(D24)="","Not Specified", IF(C24="Food", IF(LOWER(D24)="lunch","Lunch", IF(LOWER(D24)="dinner","Dinner","Snacks")), IF(C24="Travel", IF(LOWER(D24)="bus","Bus","Bus"), IF(C24="Entertainment", IF(LOWER(D24)="movie","Movie","Other"), "Other")))) -> Not Specified | G24: =IF(TRIM(F24)="","Not Provided",PROPER(TRIM(F24))) -> Not Provided | H24: 90 | I24: =IF(H24="","",VALUE(SUBSTITUTE(SUBSTITUTE(SUBSTITUTE(LOWER(H24),"rs",""),"/-",""),"$",""))) -> 90 | J24: cash | K24: =IF(TRIM(J24)="","Not Specified",IF(LOWER(J24)="upi","UPI",IF(LOWER(J24)="cash","Cash",IF(LOWER(J24)="card","Card","Other")))) -> Cash | L24: outside | M24: =IF(TRIM(L24)="","Not Specified",PROPER(TRIM(L24))) -> Outside | O24: =IF(TRIM(N24)="","Not Specified",PROPER(TRIM(N24))) -> Not Specified | P24: =TEXT(Table1[[#This Row],[Date]],"mmmm") -> November | Q24: =YEAR(Table1[[#This Row],[Date]]) -> 2026 | R24: =TEXT(Table1[[#This Row],[Date]],"dddd") -> Sunday | S24: =IF(WEEKDAY(Table1[[#This Row],[Date]],2)>5,"Weekend","Weekday") -> Weekend | T24: =IF(Table1[[#This Row],[Amount_Clean]]>500,"High","Normal") -> Normal | U24: =IF(LOWER(TRIM(Table1[[#This Row],[PaymentMode_Clean]]))="cash","Cash","Digital") -> Cash | V24: =MONTH(Table1[[#This Row],[Date]]) -> 11
A25: =DATE(2026, MONTH(Raw_Data!A25), DAY(Raw_Data!A25)) -> 46357 | B25: Travel | C25: =IF(LOWER(TRIM(B25))="food","Food",IF(LOWER(TRIM(B25))="travel","Travel",IF(LOWER(TRIM(B25))="entertainment","Entertainment","Other"))) -> Travel | D25: Bus | E25: =IF(TRIM(D25)="","Not Specified", IF(C25="Food", IF(LOWER(D25)="lunch","Lunch", IF(LOWER(D25)="dinner","Dinner","Snacks")), IF(C25="Travel", IF(LOWER(D25)="bus","Bus","Bus"), IF(C25="Entertainment", IF(LOWER(D25)="movie","Movie","Other"), "Other")))) -> Bus | F25: college bus | G25: =IF(TRIM(F25)="","Not Provided",PROPER(TRIM(F25))) -> College Bus | H25: 40 | I25: =IF(H25="","",VALUE(SUBSTITUTE(SUBSTITUTE(SUBSTITUTE(LOWER(H25),"rs",""),"/-",""),"$",""))) -> 40 | J25: cash | K25: =IF(TRIM(J25)="","Not Specified",IF(LOWER(J25)="upi","UPI",IF(LOWER(J25)="cash","Cash",IF(LOWER(J25)="card","Card","Other")))) -> Cash | L25: outside | M25: =IF(TRIM(L25)="","Not Specified",PROPER(TRIM(L25))) -> Outside | O25: =IF(TRIM(N25)="","Not Specified",PROPER(TRIM(N25))) -> Not Specified | P25: =TEXT(Table1[[#This Row],[Date]],"mmmm") -> December | Q25: =YEAR(Table1[[#This Row],[Date]]) -> 2026 | R25: =TEXT(Table1[[#This Row],[Date]],"dddd") -> Tuesday | S25: =IF(WEEKDAY(Table1[[#This Row],[Date]],2)>5,"Weekend","Weekday") -> Weekday | T25: =IF(Table1[[#This Row],[Amount_Clean]]>500,"High","Normal") -> Normal | U25: =IF(LOWER(TRIM(Table1[[#This Row],[PaymentMode_Clean]]))="cash","Cash","Digital") -> Cash | V25: =MONTH(Table1[[#This Row],[Date]]) -> 12
A26: =DATE(2026, MONTH(Raw_Data!A26), DAY(Raw_Data!A26)) -> 46023 | B26: Entertainment | C26: =IF(LOWER(TRIM(B26))="food","Food",IF(LOWER(TRIM(B26))="travel","Travel",IF(LOWER(TRIM(B26))="entertainment","Entertainment","Other"))) -> Entertainment | D26: Movie | E26: =IF(TRIM(D26)="","Not Specified", IF(C26="Food", IF(LOWER(D26)="lunch","Lunch", IF(LOWER(D26)="dinner","Dinner","Snacks")), IF(C26="Travel", IF(LOWER(D26)="bus","Bus","Bus"), IF(C26="Entertainment", IF(LOWER(D26)="movie","Movie","Other"), "Other")))) -> Movie | G26: =IF(TRIM(F26)="","Not Provided",PROPER(TRIM(F26))) -> Not Provided | H26: 350 | I26: =IF(H26="","",VALUE(SUBSTITUTE(SUBSTITUTE(SUBSTITUTE(LOWER(H26),"rs",""),"/-",""),"$",""))) -> 350 | J26: card | K26: =IF(TRIM(J26)="","Not Specified",IF(LOWER(J26)="upi","UPI",IF(LOWER(J26)="cash","Cash",IF(LOWER(J26)="card","Card","Other")))) -> Card | L26: mall | M26: =IF(TRIM(L26)="","Not Specified",PROPER(TRIM(L26))) -> Mall | O26: =IF(TRIM(N26)="","Not Specified",PROPER(TRIM(N26))) -> Not Specified | P26: =TEXT(Table1[[#This Row],[Date]],"mmmm") -> January | Q26: =YEAR(Table1[[#This Row],[Date]]) -> 2026 | R26: =TEXT(Table1[[#This Row],[Date]],"dddd") -> Thursday | S26: =IF(WEEKDAY(Table1[[#This Row],[Date]],2)>5,"Weekend","Weekday") -> Weekday | T26: =IF(Table1[[#This Row],[Amount_Clean]]>500,"High","Normal") -> Normal | U26: =IF(LOWER(TRIM(Table1[[#This Row],[PaymentMode_Clean]]))="cash","Cash","Digital") -> Digital | V26: =MONTH(Table1[[#This Row],[Date]]) -> 1
A27: =DATE(2026, MONTH(Raw_Data!A27), DAY(Raw_Data!A27)) -> 46054 | B27: Food | C27: =IF(LOWER(TRIM(B27))="food","Food",IF(LOWER(TRIM(B27))="travel","Travel",IF(LOWER(TRIM(B27))="entertainment","Entertainment","Other"))) -> Food | E27: =IF(TRIM(D27)="","Not Specified", IF(C27="Food", IF(LOWER(D27)="lunch","Lunch", IF(LOWER(D27)="dinner","Dinner","Snacks")), IF(C27="Travel", IF(LOWER(D27)="bus","Bus","Bus"), IF(C27="Entertainment", IF(LOWER(D27)="movie","Movie","Other"), "Other")))) -> Not Specified | G27: =IF(TRIM(F27)="","Not Provided",PROPER(TRIM(F27))) -> Not Provided | H27: 90 | I27: =IF(H27="","",VALUE(SUBSTITUTE(SUBSTITUTE(SUBSTITUTE(LOWER(H27),"rs",""),"/-",""),"$",""))) -> 90 | J27: cash | K27: =IF(TRIM(J27)="","Not Specified",IF(LOWER(J27)="upi","UPI",IF(LOWER(J27)="cash","Cash",IF(LOWER(J27)="card","Card","Other")))) -> Cash | L27: outside | M27: =IF(TRIM(L27)="","Not Specified",PROPER(TRIM(L27))) -> Outside | O27: =IF(TRIM(N27)="","Not Specified",PROPER(TRIM(N27))) -> Not Specified | P27: =TEXT(Table1[[#This Row],[Date]],"mmmm") -> February | Q27: =YEAR(Table1[[#This Row],[Date]]) -> 2026 | R27: =TEXT(Table1[[#This Row],[Date]],"dddd") -> Sunday | S27: =IF(WEEKDAY(Table1[[#This Row],[Date]],2)>5,"Weekend","Weekday") -> Weekend | T27: =IF(Table1[[#This Row],[Amount_Clean]]>500,"High","Normal") -> Normal | U27: =IF(LOWER(TRIM(Table1[[#This Row],[PaymentMode_Clean]]))="cash","Cash","Digital") -> Cash | V27: =MONTH(Table1[[#This Row],[Date]]) -> 2
A28: =DATE(2026, MONTH(Raw_Data!A28), DAY(Raw_Data!A28)) -> 46082 | B28: food | C28: =IF(LOWER(TRIM(B28))="food","Food",IF(LOWER(TRIM(B28))="travel","Travel",IF(LOWER(TRIM(B28))="entertainment","Entertainment","Other"))) -> Food | D28: lunch | E28: =IF(TRIM(D28)="","Not Specified", IF(C28="Food", IF(LOWER(D28)="lunch","Lunch", IF(LOWER(D28)="dinner","Dinner","Snacks")), IF(C28="Travel", IF(LOWER(D28)="bus","Bus","Bus"), IF(C28="Entertainment", IF(LOWER(D28)="movie","Movie","Other"), "Other")))) -> Lunch | F28: canteen | G28: =IF(TRIM(F28)="","Not Provided",PROPER(TRIM(F28))) -> Canteen | H28: 200/- | I28: =IF(H28="","",VALUE(SUBSTITUTE(SUBSTITUTE(SUBSTITUTE(LOWER(H28),"rs",""),"/-",""),"$",""))) -> 200 | J28: upi | K28: =IF(TRIM(J28)="","Not Specified",IF(LOWER(J28)="upi","UPI",IF(LOWER(J28)="cash","Cash",IF(LOWER(J28)="card","Card","Other")))) -> UPI | L28: outside | M28: =IF(TRIM(L28)="","Not Specified",PROPER(TRIM(L28))) -> Outside | O28: =IF(TRIM(N28)="","Not Specified",PROPER(TRIM(N28))) -> Not Specified | P28: =TEXT(Table1[[#This Row],[Date]],"mmmm") -> March | Q28: =YEAR(Table1[[#This Row],[Date]]) -> 2026 | R28: =TEXT(Table1[[#This Row],[Date]],"dddd") -> Sunday | S28: =IF(WEEKDAY(Table1[[#This Row],[Date]],2)>5,"Weekend","Weekday") -> Weekend | T28: =IF(Table1[[#This Row],[Amount_Clean]]>500,"High","Normal") -> Normal | U28: =IF(LOWER(TRIM(Table1[[#This Row],[PaymentMode_Clean]]))="cash","Cash","Digital") -> Digital | V28: =MONTH(Table1[[#This Row],[Date]]) -> 3
A29: =DATE(2026, MONTH(Raw_Data!A29), DAY(Raw_Data!A29)) -> 46113 | B29: Food | C29: =IF(LOWER(TRIM(B29))="food","Food",IF(LOWER(TRIM(B29))="travel","Travel",IF(LOWER(TRIM(B29))="entertainment","Entertainment","Other"))) -> Food | D29: dinner | E29: =IF(TRIM(D29)="","Not Specified", IF(C29="Food", IF(LOWER(D29)="lunch","Lunch", IF(LOWER(D29)="dinner","Dinner","Snacks")), IF(C29="Travel", IF(LOWER(D29)="bus","Bus","Bus"), IF(C29="Entertainment", IF(LOWER(D29)="movie","Movie","Other"), "Other")))) -> Dinner | F29: zomato | G29: =IF(TRIM(F29)="","Not Provided",PROPER(TRIM(F29))) -> Zomato | H29: 280rs | I29: =IF(H29="","",VALUE(SUBSTITUTE(SUBSTITUTE(SUBSTITUTE(LOWER(H29),"rs",""),"/-",""),"$",""))) -> 280 | J29: UPI | K29: =IF(TRIM(J29)="","Not Specified",IF(LOWER(J29)="upi","UPI",IF(LOWER(J29)="cash","Cash",IF(LOWER(J29)="card","Card","Other")))) -> UPI | L29: home | M29: =IF(TRIM(L29)="","Not Specified",PROPER(TRIM(L29))) -> Home | N29: late | O29: =IF(TRIM(N29)="","Not Specified",PROPER(TRIM(N29))) -> Late | P29: =TEXT(Table1[[#This Row],[Date]],"mmmm") -> April | Q29: =YEAR(Table1[[#This Row],[Date]]) -> 2026 | R29: =TEXT(Table1[[#This Row],[Date]],"dddd") -> Wednesday | S29: =IF(WEEKDAY(Table1[[#This Row],[Date]],2)>5,"Weekend","Weekday") -> Weekday | T29: =IF(Table1[[#This Row],[Amount_Clean]]>500,"High","Normal") -> Normal | U29: =IF(LOWER(TRIM(Table1[[#This Row],[PaymentMode_Clean]]))="cash","Cash","Digital") -> Digital | V29: =MONTH(Table1[[#This Row],[Date]]) -> 4
A30: =DATE(2026, MONTH(Raw_Data!A30), DAY(Raw_Data!A30)) -> 46143 | B30: Food | C30: =IF(LOWER(TRIM(B30))="food","Food",IF(LOWER(TRIM(B30))="travel","Travel",IF(LOWER(TRIM(B30))="entertainment","Entertainment","Other"))) -> Food | E30: =IF(TRIM(D30)="","Not Specified", IF(C30="Food", IF(LOWER(D30)="lunch","Lunch", IF(LOWER(D30)="dinner","Dinner","Snacks")), IF(C30="Travel", IF(LOWER(D30)="bus","Bus","Bus"), IF(C30="Entertainment", IF(LOWER(D30)="movie","Movie","Other"), "Other")))) -> Not Specified | G30: =IF(TRIM(F30)="","Not Provided",PROPER(TRIM(F30))) -> Not Provided | H30: 90 | I30: =IF(H30="","",VALUE(SUBSTITUTE(SUBSTITUTE(SUBSTITUTE(LOWER(H30),"rs",""),"/-",""),"$",""))) -> 90 | J30: cash | K30: =IF(TRIM(J30)="","Not Specified",IF(LOWER(J30)="upi","UPI",IF(LOWER(J30)="cash","Cash",IF(LOWER(J30)="card","Card","Other")))) -> Cash | L30: outside | M30: =IF(TRIM(L30)="","Not Specified",PROPER(TRIM(L30))) -> Outside | O30: =IF(TRIM(N30)="","Not Specified",PROPER(TRIM(N30))) -> Not Specified | P30: =TEXT(Table1[[#This Row],[Date]],"mmmm") -> May | Q30: =YEAR(Table1[[#This Row],[Date]]) -> 2026 | R30: =TEXT(Table1[[#This Row],[Date]],"dddd") -> Friday | S30: =IF(WEEKDAY(Table1[[#This Row],[Date]],2)>5,"Weekend","Weekday") -> Weekday | T30: =IF(Table1[[#This Row],[Amount_Clean]]>500,"High","Normal") -> Normal | U30: =IF(LOWER(TRIM(Table1[[#This Row],[PaymentMode_Clean]]))="cash","Cash","Digital") -> Cash | V30: =MONTH(Table1[[#This Row],[Date]]) -> 5
A31: =DATE(2026, MONTH(Raw_Data!A31), DAY(Raw_Data!A31)) -> 46174 | B31: Travel | C31: =IF(LOWER(TRIM(B31))="food","Food",IF(LOWER(TRIM(B31))="travel","Travel",IF(LOWER(TRIM(B31))="entertainment","Entertainment","Other"))) -> Travel | D31: Bus | E31: =IF(TRIM(D31)="","Not Specified", IF(C31="Food", IF(LOWER(D31)="lunch","Lunch", IF(LOWER(D31)="dinner","Dinner","Snacks")), IF(C31="Travel", IF(LOWER(D31)="bus","Bus","Bus"), IF(C31="Entertainment", IF(LOWER(D31)="movie","Movie","Other"), "Other")))) -> Bus | F31: college bus | G31: =IF(TRIM(F31)="","Not Provided",PROPER(TRIM(F31))) -> College Bus | H31: 40 | I31: =IF(H31="","",VALUE(SUBSTITUTE(SUBSTITUTE(SUBSTITUTE(LOWER(H31),"rs",""),"/-",""),"$",""))) -> 40 | J31: cash | K31: =IF(TRIM(J31)="","Not Specified",IF(LOWER(J31)="upi","UPI",IF(LOWER(J31)="cash","Cash",IF(LOWER(J31)="card","Card","Other")))) -> Cash | L31: outside | M31: =IF(TRIM(L31)="","Not Specified",PROPER(TRIM(L31))) -> Outside | O31: =IF(TRIM(N31)="","Not Specified",PROPER(TRIM(N31))) -> Not Specified | P31: =TEXT(Table1[[#This Row],[Date]],"mmmm") -> June | Q31: =YEAR(Table1[[#This Row],[Date]]) -> 2026 | R31: =TEXT(Table1[[#This Row],[Date]],"dddd") -> Monday | S31: =IF(WEEKDAY(Table1[[#This Row],[Date]],2)>5,"Weekend","Weekday") -> Weekday | T31: =IF(Table1[[#This Row],[Amount_Clean]]>500,"High","Normal") -> Normal | U31: =IF(LOWER(TRIM(Table1[[#This Row],[PaymentMode_Clean]]))="cash","Cash","Digital") -> Cash | V31: =MONTH(Table1[[#This Row],[Date]]) -> 6
A32: =DATE(2026, MONTH(Raw_Data!A32), DAY(Raw_Data!A32)) -> 46204 | B32: Entertainment | C32: =IF(LOWER(TRIM(B32))="food","Food",IF(LOWER(TRIM(B32))="travel","Travel",IF(LOWER(TRIM(B32))="entertainment","Entertainment","Other"))) -> Entertainment | D32: Movie | E32: =IF(TRIM(D32)="","Not Specified", IF(C32="Food", IF(LOWER(D32)="lunch","Lunch", IF(LOWER(D32)="dinner","Dinner","Snacks")), IF(C32="Travel", IF(LOWER(D32)="bus","Bus","Bus"), IF(C32="Entertainment", IF(LOWER(D32)="movie","Movie","Other"), "Other")))) -> Movie | G32: =IF(TRIM(F32)="","Not Provided",PROPER(TRIM(F32))) -> Not Provided | H32: 350 | I32: =IF(H32="","",VALUE(SUBSTITUTE(SUBSTITUTE(SUBSTITUTE(LOWER(H32),"rs",""),"/-",""),"$",""))) -> 350 | J32: card | K32: =IF(TRIM(J32)="","Not Specified",IF(LOWER(J32)="upi","UPI",IF(LOWER(J32)="cash","Cash",IF(LOWER(J32)="card","Card","Other")))) -> Card | L32: mall | M32: =IF(TRIM(L32)="","Not Specified",PROPER(TRIM(L32))) -> Mall | O32: =IF(TRIM(N32)="","Not Specified",PROPER(TRIM(N32))) -> Not Specified | P32: =TEXT(Table1[[#This Row],[Date]],"mmmm") -> July | Q32: =YEAR(Table1[[#This Row],[Date]]) -> 2026 | R32: =TEXT(Table1[[#This Row],[Date]],"dddd") -> Wednesday | S32: =IF(WEEKDAY(Table1[[#This Row],[Date]],2)>5,"Weekend","Weekday") -> Weekday | T32: =IF(Table1[[#This Row],[Amount_Clean]]>500,"High","Normal") -> Normal | U32: =IF(LOWER(TRIM(Table1[[#This Row],[PaymentMode_Clean]]))="cash","Cash","Digital") -> Digital | V32: =MONTH(Table1[[#This Row],[Date]]) -> 7
A33: =DATE(2026, MONTH(Raw_Data!A33), DAY(Raw_Data!A33)) -> 46235 | B33: Food | C33: =IF(LOWER(TRIM(B33))="food","Food",IF(LOWER(TRIM(B33))="travel","Travel",IF(LOWER(TRIM(B33))="entertainment","Entertainment","Other"))) -> Food | E33: =IF(TRIM(D33)="","Not Specified", IF(C33="Food", IF(LOWER(D33)="lunch","Lunch", IF(LOWER(D33)="dinner","Dinner","Snacks")), IF(C33="Travel", IF(LOWER(D33)="bus","Bus","Bus"), IF(C33="Entertainment", IF(LOWER(D33)="movie","Movie","Other"), "Other")))) -> Not Specified | G33: =IF(TRIM(F33)="","Not Provided",PROPER(TRIM(F33))) -> Not Provided | H33: 90 | I33: =IF(H33="","",VALUE(SUBSTITUTE(SUBSTITUTE(SUBSTITUTE(LOWER(H33),"rs",""),"/-",""),"$",""))) -> 90 | J33: cash | K33: =IF(TRIM(J33)="","Not Specified",IF(LOWER(J33)="upi","UPI",IF(LOWER(J33)="cash","Cash",IF(LOWER(J33)="card","Card","Other")))) -> Cash | L33: outside | M33: =IF(TRIM(L33)="","Not Specified",PROPER(TRIM(L33))) -> Outside | O33: =IF(TRIM(N33)="","Not Specified",PROPER(TRIM(N33))) -> Not Specified | P33: =TEXT(Table1[[#This Row],[Date]],"mmmm") -> August | Q33: =YEAR(Table1[[#This Row],[Date]]) -> 2026 | R33: =TEXT(Table1[[#This Row],[Date]],"dddd") -> Saturday | S33: =IF(WEEKDAY(Table1[[#This Row],[Date]],2)>5,"Weekend","Weekday") -> Weekend | T33: =IF(Table1[[#This Row],[Amount_Clean]]>500,"High","Normal") -> Normal | U33: =IF(LOWER(TRIM(Table1[[#This Row],[PaymentMode_Clean]]))="cash","Cash","Digital") -> Cash | V33: =MONTH(Table1[[#This Row],[Date]]) -> 8
A34: =DATE(2026, MONTH(Raw_Data!A34), DAY(Raw_Data!A34)) -> 46266 | B34: Entertainment | C34: =IF(LOWER(TRIM(B34))="food","Food",IF(LOWER(TRIM(B34))="travel","Travel",IF(LOWER(TRIM(B34))="entertainment","Entertainment","Other"))) -> Entertainment | D34: Movie | E34: =IF(TRIM(D34)="","Not Specified", IF(C34="Food", IF(LOWER(D34)="lunch","Lunch", IF(LOWER(D34)="dinner","Dinner","Snacks")), IF(C34="Travel", IF(LOWER(D34)="bus","Bus","Bus"), IF(C34="Entertainment", IF(LOWER(D34)="movie","Movie","Other"), "Other")))) -> Movie | G34: =IF(TRIM(F34)="","Not Provided",PROPER(TRIM(F34))) -> Not Provided | H34: 350 | I34: =IF(H34="","",VALUE(SUBSTITUTE(SUBSTITUTE(SUBSTITUTE(LOWER(H34),"rs",""),"/-",""),"$",""))) -> 350 | J34: card | K34: =IF(TRIM(J34)="","Not Specified",IF(LOWER(J34)="upi","UPI",IF(LOWER(J34)="cash","Cash",IF(LOWER(J34)="card","Card","Other")))) -> Card | L34: mall | M34: =IF(TRIM(L34)="","Not Specified",PROPER(TRIM(L34))) -> Mall | O34: =IF(TRIM(N34)="","Not Specified",PROPER(TRIM(N34))) -> Not Specified | P34: =TEXT(Table1[[#This Row],[Date]],"mmmm") -> September | Q34: =YEAR(Table1[[#This Row],[Date]]) -> 2026 | R34: =TEXT(Table1[[#This Row],[Date]],"dddd") -> Tuesday | S34: =IF(WEEKDAY(Table1[[#This Row],[Date]],2)>5,"Weekend","Weekday") -> Weekday | T34: =IF(Table1[[#This Row],[Amount_Clean]]>500,"High","Normal") -> Normal | U34: =IF(LOWER(TRIM(Table1[[#This Row],[PaymentMode_Clean]]))="cash","Cash","Digital") -> Digital | V34: =MONTH(Table1[[#This Row],[Date]]) -> 9
A35: =DATE(2026, MONTH(Raw_Data!A35), DAY(Raw_Data!A35)) -> 46296 | B35: Food | C35: =IF(LOWER(TRIM(B35))="food","Food",IF(LOWER(TRIM(B35))="travel","Travel",IF(LOWER(TRIM(B35))="entertainment","Entertainment","Other"))) -> Food | E35: =IF(TRIM(D35)="","Not Specified", IF(C35="Food", IF(LOWER(D35)="lunch","Lunch", IF(LOWER(D35)="dinner","Dinner","Snacks")), IF(C35="Travel", IF(LOWER(D35)="bus","Bus","Bus"), IF(C35="Entertainment", IF(LOWER(D35)="movie","Movie","Other"), "Other")))) -> Not Specified | G35: =IF(TRIM(F35)="","Not Provided",PROPER(TRIM(F35))) -> Not Provided | H35: 90 | I35: =IF(H35="","",VALUE(SUBSTITUTE(SUBSTITUTE(SUBSTITUTE(LOWER(H35),"rs",""),"/-",""),"$",""))) -> 90 | J35: cash | K35: =IF(TRIM(J35)="","Not Specified",IF(LOWER(J35)="upi","UPI",IF(LOWER(J35)="cash","Cash",IF(LOWER(J35)="card","Card","Other")))) -> Cash | L35: outside | M35: =IF(TRIM(L35)="","Not Specified",PROPER(TRIM(L35))) -> Outside | O35: =IF(TRIM(N35)="","Not Specified",PROPER(TRIM(N35))) -> Not Specified | P35: =TEXT(Table1[[#This Row],[Date]],"mmmm") -> October | Q35: =YEAR(Table1[[#This Row],[Date]]) -> 2026 | R35: =TEXT(Table1[[#This Row],[Date]],"dddd") -> Thursday | S35: =IF(WEEKDAY(Table1[[#This Row],[Date]],2)>5,"Weekend","Weekday") -> Weekday | T35: =IF(Table1[[#This Row],[Amount_Clean]]>500,"High","Normal") -> Normal | U35: =IF(LOWER(TRIM(Table1[[#This Row],[PaymentMode_Clean]]))="cash","Cash","Digital") -> Cash | V35: =MONTH(Table1[[#This Row],[Date]]) -> 10
A36: =DATE(2026, MONTH(Raw_Data!A36), DAY(Raw_Data!A36)) -> 46327 | B36: Travel | C36: =IF(LOWER(TRIM(B36))="food","Food",IF(LOWER(TRIM(B36))="travel","Travel",IF(LOWER(TRIM(B36))="entertainment","Entertainment","Other"))) -> Travel | D36: Bus | E36: =IF(TRIM(D36)="","Not Specified", IF(C36="Food", IF(LOWER(D36)="lunch","Lunch", IF(LOWER(D36)="dinner","Dinner","Snacks")), IF(C36="Travel", IF(LOWER(D36)="bus","Bus","Bus"), IF(C36="Entertainment", IF(LOWER(D36)="movie","Movie","Other"), "Other")))) -> Bus | F36: college bus | G36: =IF(TRIM(F36)="","Not Provided",PROPER(TRIM(F36))) -> College Bus | H36: 40 | I36: =IF(H36="","",VALUE(SUBSTITUTE(SUBSTITUTE(SUBSTITUTE(LOWER(H36),"rs",""),"/-",""),"$",""))) -> 40 | J36: cash | K36: =IF(TRIM(J36)="","Not Specified",IF(LOWER(J36)="upi","UPI",IF(LOWER(J36)="cash","Cash",IF(LOWER(J36)="card","Card","Other")))) -> Cash | L36: outside | M36: =IF(TRIM(L36)="","Not Specified",PROPER(TRIM(L36))) -> Outside | O36: =IF(TRIM(N36)="","Not Specified",PROPER(TRIM(N36))) -> Not Specified | P36: =TEXT(Table1[[#This Row],[Date]],"mmmm") -> November | Q36: =YEAR(Table1[[#This Row],[Date]]) -> 2026 | R36: =TEXT(Table1[[#This Row],[Date]],"dddd") -> Sunday | S36: =IF(WEEKDAY(Table1[[#This Row],[Date]],2)>5,"Weekend","Weekday") -> Weekend | T36: =IF(Table1[[#This Row],[Amount_Clean]]>500,"High","Normal") -> Normal | U36: =IF(LOWER(TRIM(Table1[[#This Row],[PaymentMode_Clean]]))="cash","Cash","Digital") -> Cash | V36: =MONTH(Table1[[#This Row],[Date]]) -> 11
A37: =DATE(2026, MONTH(Raw_Data!A37), DAY(Raw_Data!A37)) -> 46357 | B37: Entertainment | C37: =IF(LOWER(TRIM(B37))="food","Food",IF(LOWER(TRIM(B37))="travel","Travel",IF(LOWER(TRIM(B37))="entertainment","Entertainment","Other"))) -> Entertainment | D37: Movie | E37: =IF(TRIM(D37)="","Not Specified", IF(C37="Food", IF(LOWER(D37)="lunch","Lunch", IF(LOWER(D37)="dinner","Dinner","Snacks")), IF(C37="Travel", IF(LOWER(D37)="bus","Bus","Bus"), IF(C37="Entertainment", IF(LOWER(D37)="movie","Movie","Other"), "Other")))) -> Movie | G37: =IF(TRIM(F37)="","Not Provided",PROPER(TRIM(F37))) -> Not Provided | H37: 350 | I37: =IF(H37="","",VALUE(SUBSTITUTE(SUBSTITUTE(SUBSTITUTE(LOWER(H37),"rs",""),"/-",""),"$",""))) -> 350 | J37: card | K37: =IF(TRIM(J37)="","Not Specified",IF(LOWER(J37)="upi","UPI",IF(LOWER(J37)="cash","Cash",IF(LOWER(J37)="card","Card","Other")))) -> Card | L37: mall | M37: =IF(TRIM(L37)="","Not Specified",PROPER(TRIM(L37))) -> Mall | O37: =IF(TRIM(N37)="","Not Specified",PROPER(TRIM(N37))) -> Not Specified | P37: =TEXT(Table1[[#This Row],[Date]],"mmmm") -> December | Q37: =YEAR(Table1[[#This Row],[Date]]) -> 2026 | R37: =TEXT(Table1[[#This Row],[Date]],"dddd") -> Tuesday | S37: =IF(WEEKDAY(Table1[[#This Row],[Date]],2)>5,"Weekend","Weekday") -> Weekday | T37: =IF(Table1[[#This Row],[Amount_Clean]]>500,"High","Normal") -> Normal | U37: =IF(LOWER(TRIM(Table1[[#This Row],[PaymentMode_Clean]]))="cash","Cash","Digital") -> Digital | V37: =MONTH(Table1[[#This Row],[Date]]) -> 12
A38: =DATE(2026, MONTH(Raw_Data!A38), DAY(Raw_Data!A38)) -> 46023 | B38: food | C38: =IF(LOWER(TRIM(B38))="food","Food",IF(LOWER(TRIM(B38))="travel","Travel",IF(LOWER(TRIM(B38))="entertainment","Entertainment","Other"))) -> Food | D38: lunch | E38: =IF(TRIM(D38)="","Not Specified", IF(C38="Food", IF(LOWER(D38)="lunch","Lunch", IF(LOWER(D38)="dinner","Dinner","Snacks")), IF(C38="Travel", IF(LOWER(D38)="bus","Bus","Bus"), IF(C38="Entertainment", IF(LOWER(D38)="movie","Movie","Other"), "Other")))) -> Lunch | F38: canteen | G38: =IF(TRIM(F38)="","Not Provided",PROPER(TRIM(F38))) -> Canteen | H38: 200/- | I38: =IF(H38="","",VALUE(SUBSTITUTE(SUBSTITUTE(SUBSTITUTE(LOWER(H38),"rs",""),"/-",""),"$",""))) -> 200 | J38: upi | K38: =IF(TRIM(J38)="","Not Specified",IF(LOWER(J38)="upi","UPI",IF(LOWER(J38)="cash","Cash",IF(LOWER(J38)="card","Card","Other")))) -> UPI | L38: outside | M38: =IF(TRIM(L38)="","Not Specified",PROPER(TRIM(L38))) -> Outside | O38: =IF(TRIM(N38)="","Not Specified",PROPER(TRIM(N38))) -> Not Specified | P38: =TEXT(Table1[[#This Row],[Date]],"mmmm") -> January | Q38: =YEAR(Table1[[#This Row],[Date]]) -> 2026 | R38: =TEXT(Table1[[#This Row],[Date]],"dddd") -> Thursday | S38: =IF(WEEKDAY(Table1[[#This Row],[Date]],2)>5,"Weekend","Weekday") -> Weekday | T38: =IF(Table1[[#This Row],[Amount_Clean]]>500,"High","Normal") -> Normal | U38: =IF(LOWER(TRIM(Table1[[#This Row],[PaymentMode_Clean]]))="cash","Cash","Digital") -> Digital | V38: =MONTH(Table1[[#This Row],[Date]]) -> 1
